Traceback (most recent call last):
  File "/Users/johannes/opt/anaconda3/envs/tf2/lib/python3.7/site-packages/jupyter_cache/executors/utils.py", line 56, in single_nb_execution
    record_timing=False,
  File "/Users/johannes/opt/anaconda3/envs/tf2/lib/python3.7/site-packages/nbclient/client.py", line 1082, in execute
    return NotebookClient(nb=nb, resources=resources, km=km, **kwargs).execute()
  File "/Users/johannes/opt/anaconda3/envs/tf2/lib/python3.7/site-packages/nbclient/util.py", line 74, in wrapped
    return just_run(coro(*args, **kwargs))
  File "/Users/johannes/opt/anaconda3/envs/tf2/lib/python3.7/site-packages/nbclient/util.py", line 53, in just_run
    return loop.run_until_complete(coro)
  File "/Users/johannes/opt/anaconda3/envs/tf2/lib/python3.7/asyncio/base_events.py", line 579, in run_until_complete
    return future.result()
  File "/Users/johannes/opt/anaconda3/envs/tf2/lib/python3.7/site-packages/nbclient/client.py", line 536, in async_execute
    cell, index, execution_count=self.code_cells_executed + 1
  File "/Users/johannes/opt/anaconda3/envs/tf2/lib/python3.7/site-packages/nbclient/client.py", line 827, in async_execute_cell
    self._check_raise_for_error(cell, exec_reply)
  File "/Users/johannes/opt/anaconda3/envs/tf2/lib/python3.7/site-packages/nbclient/client.py", line 735, in _check_raise_for_error
    raise CellExecutionError.from_cell_and_msg(cell, exec_reply['content'])
nbclient.exceptions.CellExecutionError: An error occurred while executing the following cell:
------------------
#GLOVE_DIR = "./Data/glove.6B"
GLOVE_DIR = "../../../../DataSets/glove" #deepthought
embeddings_index = {}
f = open(os.path.join(GLOVE_DIR, 'glove.6B.100d.txt'))
for line in f:
    values = line.split()
    word = values[0]
    coefs = np.asarray(values[1:], dtype='float32')
    embeddings_index[word] = coefs
f.close()

print('Total %s word vectors.' % len(embeddings_index))
------------------

[0;31m---------------------------------------------------------------------------[0m
[0;31mFileNotFoundError[0m                         Traceback (most recent call last)
[0;32m<ipython-input-7-9ef61f88e7c8>[0m in [0;36m<module>[0;34m[0m
[1;32m      2[0m [0mGLOVE_DIR[0m [0;34m=[0m [0;34m"../../../../DataSets/glove"[0m [0;31m#deepthought[0m[0;34m[0m[0;34m[0m[0m
[1;32m      3[0m [0membeddings_index[0m [0;34m=[0m [0;34m{[0m[0;34m}[0m[0;34m[0m[0;34m[0m[0m
[0;32m----> 4[0;31m [0mf[0m [0;34m=[0m [0mopen[0m[0;34m([0m[0mos[0m[0;34m.[0m[0mpath[0m[0;34m.[0m[0mjoin[0m[0;34m([0m[0mGLOVE_DIR[0m[0;34m,[0m [0;34m'glove.6B.100d.txt'[0m[0;34m)[0m[0;34m)[0m[0;34m[0m[0;34m[0m[0m
[0m[1;32m      5[0m [0;32mfor[0m [0mline[0m [0;32min[0m [0mf[0m[0;34m:[0m[0;34m[0m[0;34m[0m[0m
[1;32m      6[0m     [0mvalues[0m [0;34m=[0m [0mline[0m[0;34m.[0m[0msplit[0m[0;34m([0m[0;34m)[0m[0;34m[0m[0;34m[0m[0m

[0;31mFileNotFoundError[0m: [Errno 2] No such file or directory: '../../../../DataSets/glove/glove.6B.100d.txt'
FileNotFoundError: [Errno 2] No such file or directory: '../../../../DataSets/glove/glove.6B.100d.txt'

